Workbook

Sheet COA
A1: AcctCode | B1: AcctName | C1: Levels | D1: Postable | E1: FatherNum | F1: U_TypeProduct | G1: U_Channel | H1: U_ForeignName
A2: 1 | B2: ບັນຊີ ປະເພດ 1 – ບັນ​ດາ ບັນຊີ ຊັບ​ສິນ​ໝູນ​ວຽນ | C2: 2 | D2: N | E2: 100000000000000 | F2: ? | G2: ? | H2: CLASS 1 – CURRENT ASSETS
A3: 10 | B3: ເງິນສົດໃນ​ຄັງ, ເງິນ​ຍ່ອຍ, ເງິນຝາກທະນາຄານ, ສະ​ຖາ​ບັນ​ການ​ເງິນ, ເງິນ​ຝາກ​ຄັງ​ເງິນ​ແຫ່ງ​ຊາດ," | C3: 3 | D3: N | E3: 1 | F3: ? | G3: ? | H3: Cash on Hand, Petty Cash, Cash in Banks, Financial Institutions and National Treasury
A4: 101 | B4: ​ເງິນສົດ​ໃນ​ຄັງ | C4: 4 | D4: N | E4: 10 | F4: ? | G4: ? | H4: ​Cash on Hand
A5: 1011 | B5: ​ເງິນສົດ​ເປັນ​ເງິນກີບ | C5: 5 | D5: N | E5: 101 | F5: ? | G5: ? | H5: Cash on hand – Kip
A6: 1011.01 | B6: ເງິນສົດຄັງຍ່ອຍ | C6: 6 | D6: N | E6: 1011 | F6: ? | G6: ? | H6: Cash of Sub Branch
A7: 1011.001 | B7: ເງິນສົດຄັງຍ່ອຍ | C7: 7 | D7: N | E7: 1011.01 | F7: ? | G7: ? | H7: Cash of Sub Branch
A8: 1011.01.00 | B8: ເງິນສົດຍ່ອຍ - ກີບ | C8: 8 | D8: Y | E8: 1011.001 | F8: ? | G8: ? | H8: Cash on hand - LAK
A9: 1011.01.01 | B9: ເງິນສົດຍ່ອຍ - ໂດລາ | C9: 8 | D9: Y | E9: 1011.001 | F9: ? | G9: ? | H9: Cash on hand - USD
A10: 1011.01.02 | B10: ເງິນສົດຍ່ອຍ - ບາດ | C10: 8 | D10: Y | E10: 1011.001 | F10: ? | G10: ? | H10: Cash on hand - THB
A11: 1011.01.03 | B11: ເງິນສົດຍ່ອຍ - ອື່ນໆ | C11: 8 | D11: Y | E11: 1011.001 | F11: ? | G11: ? | H11: Cash on hand – Other
A12: 1012 | B12: ເງິນສົດ​ເປັນ​ເງິນ​ຕາ​ຕ່າງ​ປະ​ເທດ | C12: 5 | D12: N | E12: 101 | F12: ? | G12: ? | H12: Cash on hand – Foreign currencies
A13: 1013 | B13: ເງິນ​ສົດ​ຍ່ອຍ | C13: 5 | D13: N | E13: 101 | F13: ? | G13: ? | H13: Petty cash
A14: 1013 | B14: ເງິນ​ສົດ​ຍ່ອຍ | C14: 6 | D14: N | E14: 1013 | F14: ? | G14: ? | H14: Petty cash
A15: 1013 | B15: ເງິນສົດໃນມື - ກີບ | C15: 7 | D15: N | E15: 1013.0 | F15: ? | G15: ? | H15: Petty cash - LAK
A16: 1013.001 | B16: ເງິນສົດໃນມື - ກີບ | C16: 8 | D16: Y | E16: 1013.00 | F16: ? | G16: ? | H16: Petty cash - LAK
A17: 1013.01 | B17: ເງິນສົດໃນມື - ໂດລາ | C17: 8 | D17: Y | E17: 1013.00 | F17: ? | G17: ? | H17: Petty Cash - USD
A18: 1013.02 | B18: ເງິນສົດໃນມື - ບາດ | C18: 8 | D18: Y | E18: 1013.00 | F18: ? | G18: ? | H18: Petty Cash - THB
A19: 1013.03 | B19: ເງິນສົດໃນມື - ອື່ນໆ | C19: 8 | D19: Y | E19: 1013.00 | F19: ? | G19: ? | H19: Petty Cash - Other
A20: 1014 | B20: ເງິນສົດກຳລັງນຳຝາກ - ທະນາຄານບໍ່ທັນໄດ້ຈົດເຂົ້າບັນຊີ | C20: 5 | D20: N | E20: 101 | F20: ? | G20: ? | H20: Cash in transit – not yet recorded in banks’ accounting
A21: 1017 | B21: ລ່ວງໜ້າ​ເງິນ​ສົດ | C21: 5 | D21: N | E21: 101 | F21: ? | G21: ? | H21: Cash advance
A22: 1017.01 | B22: ເງິນເບີກລ່ວງໜ້າ | C22: 6 | D22: N | E22: 1017 | F22: ? | G22: ? | H22: Advances
A23: 1017.02 | B23: ແບ່ງສ່ວນຈ່າຍອາກອນລາຍໄດ້ຫັກຕອນທີ່ຈ່າຍ | C23: 6 | D23: N | E23: 1017 | F23: ? | G23: ? | H23: Prepaid Withholding Tax
A24: 1017.03 | B24: ເງິນມັດຈຳ | C24: 6 | D24: N | E24: 1017 | F24: ? | G24: ? | H24: Deposits
A25: 1017.003 | B25: ເງິນມັດຈຳ | C25: 7 | D25: N | E25: 1017.03 | F25: ? | G25: ? | H25: Deposits
A26: 1017.03.01 | B26: ເງິນມັດຈຳ ບັດນໍ້າມັນ | C26: 8 | D26: Y | E26: 1017.003 | F26: ? | G26: ? | H26: Deposits Plus Card
A27: 1017.04 | B27: ແຊັກສັ່ງຈ່າຍລ່ວງໜ້າ | C27: 6 | D27: N | E27: 1017 | F27: ? | G27: ? | H27: Post Dated Cheque
A28: 1017.05 | B28: ຈ່າຍລ່ວງໜ້າ (ມັດຈຳ) | C28: 6 | D28: N | E28: 1017 | F28: ? | G28: ? | H28: Prepayment
A29: 1017.06 | B29: ຈ່າຍລ່ວງໜ້າ | C29: 6 | D29: N | E29: 1017 | F29: ? | G29: ? | H29: Prepaid - Expense
A30: 1017.07 | B30: ຈ່າຍລ່ວງໜ້າ - ຜົນຕອບແທນໃຫ້ຕົວແທນ | C30: 6 | D30: N | E30: 1017 | F30: ? | G30: ? | H30: Prepayment - Commission Due to Agent
A31: 1017.08 | B31: ໜີ້ຕ້ອງສົ່ງ ອາກອນສົ້ນເຂົ້າ ປະກັນໄພຕໍ່ | C31: 6 | D31: N | E31: 1017 | F31: ? | G31: ? | H31: Value Added Tax - Input Tax for Reinsurance Ceed
A32: 1017.09 | B32: ສ່ວນຫຼຸດໃນການຊື້ ອື່ນໆ | C32: 6 | D32: N | E32: 1017 | F32: ? | G32: ? | H32: Purchase rebates, discounts, allowances
A33: 1017.10 | B33: ອາກອນມູນຄ່າເພີ່ມລາຍຈ່າຍ | C33: 6 | D33: N | E33: 1017 | F33: ? | G33: ? | H33: Value added taxies. Expenditure 07%
A34: 1017.11 | B34: ອາກອນມູນຄ່າເພີ່ມຫັກໃນເດືອນກ່ອນຍັງບໍ່ໝົດ | C34: 6 | D34: N | E34: 1017 | F34: ? | G34: ? | H34: Value added taies that was not fully deducted from the previous months
A35: 1017.12 | B35: ໜ້າຕ້ອງຮັບ MSITB | C35: 6 | D35: N | E35: 1017 | F35: ? | G35: ? | H35: Account Receivable for MSITB
A36: 1017.13 | B36: ໜີ້ຕ້ອງຮັບ ເງິນຝາກຄໍ້າປະກັນ | C36: 6 | D36: N | E36: 1017 | F36: ? | G36: ? | H36: Account receivable for Security Deposit to Bank
A37: 102 | B37: ເງິນຝາກທະນາຄານ, ສະຖາບັນການເງິນ ແລະ ສະ​ຖາ​ບັນ​ທີ່​ຄ້າຍ​ຄື​ກັນ" | C37: 4 | D37: N | E37: 10 | F37: ? | G37: ? | H37: Banks, Financial and Similar Institutions
A38: 1021 | B38: ເງິນຝາກທະນາຄານເປັນ​ເງິນ​ກີບ | C38: 5 | D38: N | E38: 102 | F38: ? | G38: ? | H38: Bank accounts in Kip
A39: 1021.01 | B39: ເງິນຝາກທະນາຄານບັນຊີກະແສລາຍວັນ | C39: 6 | D39: N | E39: 1021 | F39: ? | G39: ? | H39: Cash at Banks - Current Accounts
A40: 1021.001 | B40: ເງິນຝາກທະນາຄານບັນຊີກະແສລາຍວັນ | C40: 7 | D40: N | E40: 1021.01 | F40: ? | G40: ? | H40: Cash at Banks - Current Accounts
...

Sheet COA_MSIGSX 09.02.2026
A1: Code | B1: Name | C1: ActiveAccount | D1: FatherAccountKey | E1: U_TypeProduct | F1: U_Channel | G1: U_ForeignName | H1: U_Grouping
A2: AcctCode | B2: AcctName | C2: Postable | D2: FatherNum | E2: U_TypeProduct | F2: U_Channel | G2: U_ForeignName | H2: U_Grouping
A3: 1 | B3: ບັນຊີ ປະເພດ 1 – ບັນ​ດາ ບັນຊີ ຊັບ​ສິນ​ໝູນ​ວຽນ | C3: tNO | D3: 100000000000000 | G3: CLASS 1 – CURRENT ASSETS | H3: =VLOOKUP(A3,COA!$A:$H,8,FALSE) -> CLASS 1 – CURRENT ASSETS
A4: 10 | B4: ເງິນສົດໃນ​ຄັງ, ເງິນ​ຍ່ອຍ, ເງິນຝາກທຄ, ສະ​ຖາ​ບັນ​ການ​ເງິນ, ເງິນ​ຝາກ​ຄັງ​ເງິນ​ແຫ່ງ​ຊາດ | C4: tNO | D4: 1 | G4: Cash on Hand, Petty Cash, Cash in Banks, Financial Institutions and National Treasury | H4: =VLOOKUP(A4,COA!$A:$H,8,FALSE) -> Cash on Hand, Petty Cash, Cash in Banks, Financial Institutions and National Treasury
A5: 101 | B5: ​ເງິນສົດ​ໃນ​ຄັງ | C5: tNO | D5: 10 | G5: ​Cash on Hand | H5: =VLOOKUP(A5,COA!$A:$H,8,FALSE) -> ​Cash on Hand
A6: 1011 | B6: ​ເງິນສົດ​ເປັນ​ເງິນກີບ | C6: tNO | D6: 101 | G6: Cash on hand – Kip | H6: =VLOOKUP(A6,COA!$A:$H,8,FALSE) -> Cash on hand – Kip
A7: 1011.01 | B7: ເງິນສົດຄັງຍ່ອຍ | C7: tNO | D7: 1011 | G7: Cash of Sub Branch | H7: =VLOOKUP(A7,COA!$A:$H,8,FALSE) -> Cash of Sub Branch
A8: 1011.001 | B8: ເງິນສົດຄັງຍ່ອຍ | C8: tNO | D8: 1011.01 | G8: Cash of Sub Branch | H8: =VLOOKUP(A8,COA!$A:$H,8,FALSE) -> Cash of Sub Branch
A9: 1011.01.00 | B9: ເງິນສົດຍ່ອຍ-ກີບ | C9: tYES | D9: 1011.001 | G9: Cash on hand-LAK | H9: =VLOOKUP(A9,COA!$A:$H,8,FALSE) -> Cash on hand - LAK
A10: 1011.01.01 | B10: ເງິນສົດຍ່ອຍ-ໂດລາ | C10: tYES | D10: 1011.001 | G10: Cash on hand-USD | H10: =VLOOKUP(A10,COA!$A:$H,8,FALSE) -> Cash on hand - USD
A11: 1011.01.02 | B11: ເງິນສົດຍ່ອຍ-ບາດ | C11: tYES | D11: 1011.001 | G11: Cash on hand-THB | H11: =VLOOKUP(A11,COA!$A:$H,8,FALSE) -> Cash on hand - THB
A12: 1011.01.03 | B12: ເງິນສົດຍ່ອຍ-ອື່ນໆ | C12: tYES | D12: 1011.001 | G12: Cash on hand – Other | H12: =VLOOKUP(A12,COA!$A:$H,8,FALSE) -> Cash on hand – Other
A13: 1012 | B13: ເງິນສົດ​ເປັນ​ເງິນ​ຕາ​ຕ່າງ​ປະ​ເທດ | C13: tNO | D13: 101 | G13: Cash on hand – Foreign currencies | H13: =VLOOKUP(A13,COA!$A:$H,8,FALSE) -> Cash on hand – Foreign currencies
A14: 1013 | B14: ເງິນ​ສົດ​ຍ່ອຍ | C14: tNO | D14: 101 | G14: Petty cash | H14: =VLOOKUP(A14,COA!$A:$H,8,FALSE) -> Petty cash
A15: 1013 | B15: ເງິນ​ສົດ​ຍ່ອຍ | C15: tNO | D15: 1013 | G15: Petty cash | H15: =VLOOKUP(A15,COA!$A:$H,8,FALSE) -> Petty cash
A16: 1013 | B16: ເງິນສົດໃນມື-ກີບ | C16: tNO | D16: 1013.0 | G16: Petty cash-LAK | H16: =VLOOKUP(A16,COA!$A:$H,8,FALSE) -> Petty cash
A17: 1013.001 | B17: ເງິນສົດໃນມື-ກີບ | C17: tYES | D17: 1013.00 | G17: Petty cash-LAK | H17: =VLOOKUP(A17,COA!$A:$H,8,FALSE) -> Petty cash - LAK
A18: 1013.01 | B18: ເງິນສົດໃນມື-ໂດລາ | C18: tYES | D18: 1013.00 | G18: Petty Cash-USD | H18: =VLOOKUP(A18,COA!$A:$H,8,FALSE) -> Petty Cash - USD
A19: 1013.02 | B19: ເງິນສົດໃນມື-ບາດ | C19: tYES | D19: 1013.00 | G19: Petty Cash-THB | H19: =VLOOKUP(A19,COA!$A:$H,8,FALSE) -> Petty Cash - THB
A20: 1013.03 | B20: ເງິນສົດໃນມື-ອື່ນໆ | C20: tYES | D20: 1013.00 | G20: Petty Cash-Other | H20: =VLOOKUP(A20,COA!$A:$H,8,FALSE) -> Petty Cash - Other
A21: 1014 | B21: ເງິນສົດກຳລັງນຳຝາກ-ທຄບໍ່ທັນໄດ້ຈົດເຂົ້າບັນຊີ | C21: tNO | D21: 101 | G21: Cash in transit – not yet recorded in banks’ accounting | H21: =VLOOKUP(A21,COA!$A:$H,8,FALSE) -> Cash in transit – not yet recorded in banks’ accounting
A22: 1017 | B22: ລ່ວງໜ້າ​ເງິນ​ສົດ | C22: tNO | D22: 101 | G22: Cash advance | H22: =VLOOKUP(A22,COA!$A:$H,8,FALSE) -> Cash advance
A23: 1017.01 | B23: ເງິນເບີກລ່ວງໜ້າ | C23: tNO | D23: 1017 | G23: Advances | H23: =VLOOKUP(A23,COA!$A:$H,8,FALSE) -> Advances
A24: 1017.02 | B24: ແບ່ງສ່ວນຈ່າຍອາກອນລາຍໄດ້ຫັກຕອນທີ່ຈ່າຍ | C24: tNO | D24: 1017 | G24: Prepaid Withholding Tax | H24: =VLOOKUP(A24,COA!$A:$H,8,FALSE) -> Prepaid Withholding Tax
A25: 1017.03 | B25: ເງິນມັດຈຳ | C25: tNO | D25: 1017 | G25: Deposits | H25: =VLOOKUP(A25,COA!$A:$H,8,FALSE) -> Deposits
A26: 1017.003 | B26: ເງິນມັດຈຳ | C26: tNO | D26: 1017.03 | G26: Deposits | H26: =VLOOKUP(A26,COA!$A:$H,8,FALSE) -> Deposits
A27: 1017.03.01 | B27: ເງິນມັດຈຳ ບັດນໍ້າມັນ | C27: tYES | D27: 1017.003 | G27: Deposits Plus Card | H27: =VLOOKUP(A27,COA!$A:$H,8,FALSE) -> Deposits Plus Card
A28: 1017.04 | B28: ແຊັກສັ່ງຈ່າຍລ່ວງໜ້າ | C28: tNO | D28: 1017 | G28: Post Dated Cheque | H28: =VLOOKUP(A28,COA!$A:$H,8,FALSE) -> Post Dated Cheque
A29: 1017.05 | B29: ຈ່າຍລ່ວງໜ້າ (ມັດຈຳ) | C29: tNO | D29: 1017 | G29: Prepayment | H29: =VLOOKUP(A29,COA!$A:$H,8,FALSE) -> Prepayment
A30: 1017.06 | B30: ຈ່າຍລ່ວງໜ້າ | C30: tNO | D30: 1017 | G30: Prepaid-Expense | H30: =VLOOKUP(A30,COA!$A:$H,8,FALSE) -> Prepaid - Expense
A31: 1017.07 | B31: ຈ່າຍລ່ວງໜ້າ-ຜົນຕອບແທນໃຫ້ຕົວແທນ | C31: tNO | D31: 1017 | G31: Prepayment-Commission Due to Agent | H31: =VLOOKUP(A31,COA!$A:$H,8,FALSE) -> Prepayment - Commission Due to Agent
A32: 1017.08 | B32: ໜີ້ຕ້ອງສົ່ງ ອາກອນສົ້ນເຂົ້າ ປກພ ຕໍ່ | C32: tNO | D32: 1017 | G32: Value Added Tax-Input Tax for Reinsurance Ceed | H32: =VLOOKUP(A32,COA!$A:$H,8,FALSE) -> Value Added Tax - Input Tax for Reinsurance Ceed
A33: 1017.09 | B33: ສ່ວນຫຼຸດໃນການຊື້ ອື່ນໆ | C33: tNO | D33: 1017 | G33: Purchase rebates, discounts, allowances | H33: =VLOOKUP(A33,COA!$A:$H,8,FALSE) -> Purchase rebates, discounts, allowances
A34: 1017.10 | B34: ອາກອນມູນຄ່າເພີ່ມລາຍຈ່າຍ | C34: tNO | D34: 1017 | G34: Value added taxies. Expenditure 07% | H34: =VLOOKUP(A34,COA!$A:$H,8,FALSE) -> Value added taxies. Expenditure 07%
A35: 1017.11 | B35: ອາກອນມູນຄ່າເພີ່ມຫັກໃນເດືອນກ່ອນຍັງບໍ່ໝົດ | C35: tNO | D35: 1017 | G35: Value added taies that was not fully deducted from the previous months | H35: =VLOOKUP(A35,COA!$A:$H,8,FALSE) -> Value added taies that was not fully deducted from the previous months
A36: 1017.12 | B36: ໜ້າຕ້ອງຮັບ MSITB | C36: tNO | D36: 1017 | G36: Account Receivable for MSITB | H36: =VLOOKUP(A36,COA!$A:$H,8,FALSE) -> Account Receivable for MSITB
A37: 1017.13 | B37: ໜີ້ຕ້ອງຮັບ ເງິນຝາກຄໍ້າປະກັນ | C37: tNO | D37: 1017 | G37: Account receivable for Security Deposit to Bank | H37: =VLOOKUP(A37,COA!$A:$H,8,FALSE) -> Account receivable for Security Deposit to Bank
A38: 102 | B38: ເງິນຝາກທຄ, ສະຖາບັນການເງິນ ແລະ ສະ​ຖາ​ບັນ​ທີ່​ຄ້າຍ​ຄື​ກັນ" | C38: tNO | D38: 10 | G38: Banks, Financial and Similar Institutions | H38: =VLOOKUP(A38,COA!$A:$H,8,FALSE) -> Banks, Financial and Similar Institutions
A39: 1021 | B39: ເງິນຝາກທຄເປັນ​ເງິນ​ກີບ | C39: tNO | D39: 102 | G39: Bank accounts in Kip | H39: =VLOOKUP(A39,COA!$A:$H,8,FALSE) -> Bank accounts in Kip
A40: 1021.01 | B40: ເງິນຝາກທຄບັນຊີກະແສລາຍວັນ | C40: tNO | D40: 1021 | G40: Cash at Banks-Current Accounts | H40: =VLOOKUP(A40,COA!$A:$H,8,FALSE) -> Cash at Banks - Current Accounts
...
